Workbook

Sheet Sheet4
A3: Row Labels | B3: Count of Đơn vị
A4: Anh Sơn | B4: 14 | D4: Anh Sơn | E4: =COUNTIF(Sheet1!G:G,Sheet4!D4) -> 20
A5: Con Cuông | B5: 8 | D5: Con Cuông | E5: =COUNTIF(Sheet1!G:G,Sheet4!D5) -> 8
A6: Diễn Châu | B6: 32 | D6: Diễn Châu | E6: =COUNTIF(Sheet1!G:G,Sheet4!D6) -> 38
A7: Đô Lương | B7: 21 | D7: Đô Lương | E7: =COUNTIF(Sheet1!G:G,Sheet4!D7) -> 24
A8: Hưng Nguyên | B8: 2 | D8: Hưng Nguyên | E8: =COUNTIF(Sheet1!G:G,Sheet4!D8) -> 0
A9: Kỳ Sơn | B9: 8 | D9: Kỳ Sơn | E9: =COUNTIF(Sheet1!G:G,Sheet4!D9) -> 8
A10: Nam Đàn | B10: 23 | D10: Nam Đàn | E10: =COUNTIF(Sheet1!G:G,Sheet4!D10) -> 26
A11: Nghi Lộc | B11: 32 | D11: Nghi Lộc | E11: =COUNTIF(Sheet1!G:G,Sheet4!D11) -> 34
A12: Nghĩa Đàn | B12: 58 | D12: Nghĩa Đàn | E12: =COUNTIF(Sheet1!G:G,Sheet4!D12) -> 60
A13: Quế Phong | B13: 5 | D13: Quế Phong | E13: =COUNTIF(Sheet1!G:G,Sheet4!D13) -> 5
A14: Quỳ Châu | B14: 5 | D14: Quỳ Châu | E14: =COUNTIF(Sheet1!G:G,Sheet4!D14) -> 6
A15: Quỳ Hợp | B15: 24 | D15: Quỳ Hợp | E15: =COUNTIF(Sheet1!G:G,Sheet4!D15) -> 26
... A23: Yên Thành | B23: 32 | D23: Yên Thành | E23: =COUNTIF(Sheet1!G:G,Sheet4!D23) -> 35
A24: Grand Total | B24: 709

Sheet Sheet1
A1: STT | B1: Tên cơ sở hành nghề | C1: Người phụ trách chuyên môn | D1: Địa điểm hành nghề | E1: Hình thức tổ chức | F1: Số giấy phép hoạt động | G1: Đơn vị
A2: 1 | B2: PHÒNG KHÁM BỆNH RĂNG-HÀM-MẶT TƯ NHÂN 108 | C2: Võ Duy Khánh | D2: Số 96- Đ. Ngư Hải- TP.Vinh | E2: Phòng khám chuyên khoa | F2: 0053/NA-GPHĐ | G2: TTKDGP
A3: 2 | B3: PHÒNG KHÁM BỆNH SẢN PHỤ KHOA TƯ NHÂN | C3: Hoàng Thị Thu | D3: Số 23,ngõ1A- Đ. Trần Thủ Độ- TP.Vinh | E3: Phòng khám chuyên khoa | F3: 0056/NA-GPHĐ | G3: TTKDGP
A4: 3 | B4: PHÒNG KHÁM BỆNH SẢN PHỤ KHOA TƯ NHÂN | C4: Đặng Thị Ngọc | D4: Số 03, Vinaconec 9- Đ. Lê-Nin - TP.Vinh | E4: Phòng khám chuyên khoa | F4: 0057/NA-GPHĐ | G4: TTKDGP
A5: 4 | B5: PHÒNG KHÁM BỆNH SẢN PHỤ KHOA TƯ NHÂN | C5: Lương Thị Bích Ngân | D5: Số 18,ngõ 128- Đ. Lê Hồng Phong- TP.Vinh | E5: Phòng khám chuyên khoa | F5: 0058/NA-GPHĐ | G5: TTKDGP
A6: 5 | B6: PHÒNG KHÁM BỆNH NỘI KHOA TỔNG HỢP TƯ NHÂN | C6: Trần Quốc Thành | D6: Khối Hòa Đông- TT Hòa Bình- Tương Dương | E6: Phòng khám chuyên khoa | F6: 0059/NA-GPHĐ | G6: Tương Dương
A7: 6 | B7: PHÒNG KHÁM BỆNH RĂNG-HÀM-MẶT TƯ NHÂN | C7: Nguyễn Thị Phương Thảo | D7: Khối 3- TT Quán Hành- Nghi Lộc | E7: Phòng khám chuyên khoa | F7: 0060/NA-GPHĐ | G7: Nghi Lộc
A8: 7 | B8: PHÒNG KHÁM BỆNH RĂNG-HÀM-MẶT TƯ NHÂN | C8: Nguyễn Thị Thu | D8: Khối 2- Thị trấn Con Cuông | E8: Phòng khám chuyên khoa | F8: 0061/NA-GPHĐ | G8: Con Cuông
A9: 8 | B9: PHÒNG CHẨN TRỊ Y HỌC CỔ TRUYỀN TƯ NHÂN | C9: Trần Thị Mai Hòa | D9: Số 18- Đ. Đinh Công Tráng - TP. Vinh | E9: Phòng YHCT | F9: 0063/NA-GPHĐ | G9: TTKDGP
A10: 9 | B10: PHÒNG KHÁM BỆNH RĂNG-HÀM-MẶT TƯ NHÂN | C10: Lê Xuân Thu | D10: Số 04/Ngõ 47- Đ. Hoàng Trọng Trì- Hưng Lộc-TP.Vinh | E10: Phòng khám chuyên khoa | F10: 0064/NA-GPHĐ | G10: TTKDGP
A11: 10 | B11: PHÒNG KHÁM BỆNH SẢN PHỤ KHOA TƯ NHÂN THANH TÂM | C11: Lê Thị Thanh Tâm | D11: Số 04/Ngõ 10- Đ. Hoàng Phan Thái- Nghi Phú-TP.Vinh | E11: Phòng khám chuyên khoa | F11: 0066/NA-GPHĐ | G11: TTKDGP
A12: 11 | B12: PHÒNG KHÁM BỆNH SẢN PHỤ KHOA TƯ NHÂN | C12: Lô Thị Hiền | D12: Khối Bắc Hồ- Thị trấn huyện Quỳ Hợp | E12: Phòng khám chuyên khoa | F12: 0067/NA-GPHĐ | G12: Quỳ Hợp
A13: 12 | B13: PHÒNG KHÁM CHẨN ĐOÁN HÌNH ẢNH TƯ NHÂN | C13: Trần Khánh Trường | D13: Số 167 – Đ. Nguyễn Phong Sắc – TP.Vinh | E13: Phòng khám chuyên khoa | F13: 0070/NA-GPHĐ | G13: TTKDGP
... A636: 635 | B636: PHÒNG KHÁM CHUYÊN KHOA MẮT SÀI GÒN ĐÔ LƯƠNG TRỰC THUỘC CÔNG TY CP BV MẮT SÀI GÒN VINH | C636: Nguyễn Thị Vân | D636: Khối 9, thị trấn Đô Lương, huyện Đô Lương Nghệ An | E636: Phòng khám chuyên khoa | F636: 1368/NA-GPHĐ | G636: Đô Lương
A637: 636 | B637: PHÒNG KHÁM CHUYÊN KHOA NHI TRÍ ĐỨC | C637: Đồng Thị Hằng | D637: Số 111B, đường Phạm Đình Toái, TP. Vinh, tỉnh Nghệ An | E637: Phòng khám chuyên khoa | G637: TTKDGP | H637: 1370/NA-GPHĐ
A638: 637 | B638: PHÒNG KHÁM CHUYÊN KHOA NHI BÁC SỸ NGUYỆT | C638: Vương Thị Minh Nguyệt | D638: Số 42B, đường Hoàng Trọng Trì, xã Hưng Lộc, TP. Vinh, Nghệ An | E638: Phòng khám chuyên khoa | G638: TTKDGP
A639: 638 | B639: PHÒNG KHÁM CHUYÊN KHOA DA LIỄU TRỰC THUỘC CÔNG TY CP THẨM MỸ OHIO | C639: Nguyễn Thị Thanh Hoà | D639: Số 108 Trần Phú, phường Hồng Sơn, TP. Vinh, Nghệ An | E639: Phòng khám chuyên khoa | G639: TTKDGP
A640: 639 | B640: PHÒNG KHÁM CHUYÊN KHOA YHCT TIẾN PHÁT | C640: Nguyễn Đình Tiến | D640: Số 54 An Dương Vương, TP. Vinh, Nghệ An | E640: Phòng khám chuyên khoa | G640: TTKDGP
A641: 640 | B641: PHÒNG KHÁM SẢN PHỤ KHOA VIETCARE | C641: Nguyễn Thị Dung | D641: Số 22 Nguyễn Sỹ Sách, phường Hưng Bình, TP. Vinh, Nghệ An | E641: Phòng khám chuyên khoa | G641: TTKDGP
A642: 641 | B642: PHÒNG KHÁM CHUYÊN KHOA PHẪU THUẬT TẠO HÌNH THẨM MỸ OSHUN | C642: Đậu Huy Hoàn | D642: Số 21 Phan Đình Phùng, TP. Vinh, tỉnh Nghệ An | E642: Phòng khám chuyên khoa | G642: TTKDGP
A643: 642 | B643: PHÒNG KHÁM CHUYÊN KHOA TẠO HÌNH THẨM MỸ MAILISA 3 | C643: Nguyễn Ngọc Xuyến | D643: Tầng 5, 132 Nguyễn Văn Cừ, TP Vinh Nghệ An | E643: Phòng khám chuyên khoa | G643: TTKDGP
A644: 643 | B644: PHÒNG KHÁM CHUYÊN KHOA MẮT BÁC SỸ THUỶ | C644: Lê Thị Thanh Thuỷ | D644: Quốc lộ 46, khối Nam Bắc Sơn, thị trấn Nam Đàn, huyện Nam Đàn, Nghệ An | E644: Phòng khám chuyên khoa | F644: 1375/NA-GPHĐ | G644: Nam Đàn
A645: 644 | B645: PHÒNG KHÁM CHUYÊN KHOA NỘI AN TRUNG ĐẠI Y THUỘC CÔNG TY TNHH AN TRUNG ĐẠI Y | C645: Nguyễn Đông Phi | D645: Xoam An Trung, xã Nghĩa An, huyện Nghĩa Đàn, tỉnh Nghệ An | E645: Phòng khám chuyên khoa | F645: 1378/NA-GPHĐ | G645: Nghĩa Đàn
A646: 645 | B646: PHÒNG KHÁM CHUYÊN KHOA PHỤ SẢN - THS HOÀNH - ANHKA.EMRI | C646: Lê Văn Hoành | D646: 77B, đường Tôn Thất Tùng. thàmh phố Vinh, Nghệ An | E646: Phòng khám chuyên khoa | F646: 1376/NA-GPHĐ | G646: TTKDGP
A647: 646 | B647: PHÒNG KHÁM CHUYÊN KHOA NHI HỒNG BÀNG | C647: Nguyễn Thị Tâm | D647: Số 156 đường Hồng Bàng, phường Quang Trung, thành phố Vinh, Nghệ An | E647: Phòng khám chuyên khoa | F647: 1380/NA-GPHĐ | G647: TTKDGP
A648: 647 | B648: PHÒNG KHÁM CHUYÊN KHOA RĂNG HÀM MẶT HOÀNG GIA | C648: Nguyễn Thị Phương | D648: Khối 3A, thị trấn Dùng, Thanh Chương, Nghệ An | E648: Phòng khám chuyên khoa | F648: 01391/NA-GPHĐ | G648: Thanh Chương
A649: 648 | B649: PHÒNG KHÁM CHUYÊN KHOA RĂNG HÀM MẶT TIẾN THẮNG | C649: Hoàng Thị Minh | D649: Khối 3, thị trấn Hoa Thành, Yên Thành, Nghệ An | E649: Phòng khám chuyên khoa | F649: 01392/NA-GPHĐ | G649: Yên Thành
A650: 649 | B650: PHÒNG KHÁM Y HỌC CỔ TRUYỀN ĐẶNG GIA ĐƯỜNG | C650: Đặng Hồng Trương | D650: Xóm Mỹ Giang, xã Thịnh Mỹ, Hưng Nguyên, Nghệ An | E650: Phòng khám chuyên khoa | F650: 01393/NA-GPHĐ | G650: Vinh 1
A651: 650 | B651: PHÒNG KHÁM CHUYÊN KHOA PHỤ SẢN VIỆT THANH | C651: Nguyễn Thị Bích Thảo | D651: Số 201, khối 5A, đường 1-9, thị trấn Dùng, Thanh Chương, Nghệ An | E651: Phòng khám chuyên khoa | F651: 01390/NA-GPHĐ | G651: Thanh Chương
A652: 651 | B652: PHÒNG KHÁM CHUYÊN KHOA TAI MŨI HỌNG BÁC SỸ CHIẾN | C652: Tôn Thanh Chiến | D652: Xóm Đội Cung, xã Trung Thành, Yên Thành, Nghệ An | E652: Phòng khám chuyên khoa | F652: 01389/NA-GPHĐ | G652: Yên Thành
A653: 652 | B653: PHÒNG KHÁM CHUYÊN KHOA PHỤ SẢN BẢO NGÂN | C653: Ngô Thị Ngân | D653: Xóm 5, xã Tăng Thành, Yên Thành, Nghệ An | E653: Phòng khám chuyên khoa | F653: 01388/NA-GPHĐ | G653: Yên Thành
A654: 653 | B654: PHÒNG KHÁM CHUYÊN KHOA TAI MŨI HỌNG THẾ ANH | C654: Võ Thé Anh | D654: Số 85, đường Đinh Lễ, phường Hưng Dũng, Vinh, Nghệ An | E654: Phòng khám chuyên khoa | F654: 01387/NA-GPHĐ | G654: TTKDGP
A655: 654 | B655: PHÒNG KHÁM CHUYÊN KHOA NỘI LÂM ĐÔNG | C655: Đinh Thị Hạnh Lâm | D655: Số 8A, ngõ 189, đường Phong Định Cảng, phường Trường Thi, tp Vinh, Nghệ An | E655: Phòng khám chuyên khoa | F655: 01385/NA-GPHĐ | G655: TTKDGP
... A708: 707 | B708: PHÒNG KHÁM RĂNG HÀM MẶT BÁC SĨ THÀNH | C708: Đậu Đức Thành | D708: Xóm 02, xã Kim Liên, tỉnh Nghệ An | E708: Phòng khám Răng Hàm Mặt | F708: 01449/NA-GPHĐ | G708: Anh Sơn
A709: 708 | B709: PHÒNG KHÁM RĂNG HÀM MẶT ĐỨC PHƯƠNG | D709: Số 178 đường Nguyễn Trãi, phường Thái Hòa, tỉnh Nghệ An | E709: Phòng khám Răng Hàm Mặt | F709: 01450/NA-GPHĐ | G709: Nghĩa Đàn
A710: 709 | B710: PHÒNG KHÁM NỘI TIÊU HÓA LAM HỒNG TRỰC THUỘC CÔNG TY CỔ PHẦN Y TẾ HÀ AN | D710: Tầng 2,3 nhà DO16, đại lộ Lê Nin, phường Vinh Phú, tỉnh Nghệ An | E710: Phòng khám chuyên khoa | F710: 01451/NA-GPHĐ | G710: TTKDGP
A711: 710 | B711: Phòng khám đa khoa Hòa Bình thuộc Công ty TNHH Khám chữa bệnh Hòa Bình | D711: Số 203 Xóm Hòa Nam, Xã Tương Dương | E711: Phòng khám Đa khoa | F711: 01338/NA-GPHĐ | G711: Tương Dương
A712: 711 | B712: Phòng khám đa khoa Hà Nội - Quỳ Châu trực thuộc công ty cổ phần khám chữa bệnh Đoàn Kết II | D712: Số 57 Thẳm Ồm, thôn Tân Hương, Xã Quỳ Châu | E712: Phòng khám Đa khoa | F712: 1235/NA-GPHĐ | G712: Quỳ Châu
A713: 712 | B713: Phòng khám Đa khoa Đông Hiếu thuộc Công ty Cổ phần KCB Đông Hiếu | D713: Xóm Đông Mỹ, Xã Đông Hiếu | E713: Phòng khám Đa khoa | F713: 1092/NA-GPHĐ | G713: Nghĩa Đàn
A714: 713 | B714: Phòng khám đa khoa Tân Thanh trực thuộc Công ty cổ phần tổng hợp Hà An | D714: Thôn 5A, Xã Đại Đồng | E714: Phòng khám Đa khoa | F714: 1379/NA-GPHĐ | G714: Thanh Chương
...

Sheet Sheet2
A3: TTKDGP | B3: =COUNTIF(Sheet1!G:G,Sheet2!A3) -> 333 | D3: Anh Sơn | E3: 14 | F3: =VLOOKUP(D3,$A$3:$B$21,2,0) -> 20
A4: Kỳ Sơn | B4: =COUNTIF(Sheet1!G:G,Sheet2!A4) -> 8 | D4: Con Cuông | E4: 8 | F4: =VLOOKUP(D4,$A$3:$B$21,2,0) -> 8
A5: Vinh 2 | B5: =COUNTIF(Sheet1!G:G,Sheet2!A5) -> 13 | D5: Diễn Châu | E5: 32 | F5: =VLOOKUP(D5,$A$3:$B$21,2,0) -> 38
A6: Tân Kỳ | B6: =COUNTIF(Sheet1!G:G,Sheet2!A6) -> 13 | D6: Đô Lương | E6: 21 | F6: =VLOOKUP(D6,$A$3:$B$21,2,0) -> 24
A7: Đô Lương | B7: =COUNTIF(Sheet1!G:G,Sheet2!A7) -> 24 | D7: Hưng Nguyên | E7: 2 | F7: =VLOOKUP(D7,$A$3:$B$21,2,0) -> #N/A
A8: Nghi Lộc | B8: =COUNTIF(Sheet1!G:G,Sheet2!A8) -> 34 | D8: Kỳ Sơn | E8: 8 | F8: =VLOOKUP(D8,$A$3:$B$21,2,0) -> 8
A9: Quỳ Châu | B9: =COUNTIF(Sheet1!G:G,Sheet2!A9) -> 6 | D9: Nam Đàn | E9: 23 | F9: =VLOOKUP(D9,$A$3:$B$21,2,0) -> 26
A10: Anh Sơn | B10: =COUNTIF(Sheet1!G:G,Sheet2!A10) -> 20 | D10: Nghi Lộc | E10: 32 | F10: =VLOOKUP(D10,$A$3:$B$21,2,0) -> 34
A11: Diễn Châu | B11: =COUNTIF(Sheet1!G:G,Sheet2!A11) -> 38 | D11: Nghĩa Đàn | E11: 58 | F11: =VLOOKUP(D11,$A$3:$B$21,2,0) -> 60
A12: Quỳnh Lưu | B12: =COUNTIF(Sheet1!G:G,Sheet2!A12) -> 53 | D12: Quế Phong | E12: 5 | F12: =VLOOKUP(D12,$A$3:$B$21,2,0) -> 5
A13: Nghĩa Đàn | B13: =COUNTIF(Sheet1!G:G,Sheet2!A13) -> 60 | D13: Quỳ Châu | E13: 5 | F13: =VLOOKUP(D13,$A$3:$B$21,2,0) -> 6
A14: Tương Dương | B14: =COUNTIF(Sheet1!G:G,Sheet2!A14) -> 7 | D14: Quỳ Hợp | E14: 24 | F14: =VLOOKUP(D14,$A$3:$B$21,2,0) -> 26
... A21: Quế Phong | B21: =COUNTIF(Sheet1!G:G,Sheet2!A21) -> 5 | D21: Vinh 2 | E21: 13 | F21: =VLOOKUP(D21,$A$3:$B$21,2,0) -> 13
D22: Yên Thành | E22: 32 | F22: =VLOOKUP(D22,$A$3:$B$21,2,0) -> 35

Sheet Sheet3
A1: STT | B1: Đơn vị | C1: Số lượng phòng khám | D1: Số lượng Cửa hàng thuốc | E1: CT01_VNPT Home & Clinic | H1: CT2_VNPT Pharmacy
E2: KHG PK sử dụng gói cước thử nghiệm (TB) | F2: KHG PK sử dụng gói cước có phí (TB) | G2: KHG Thâm canh dịch vụ (TB) | H2: KHG phát triển dịch vụ VNPT Pharmcy (có phí)
B3: Tỷ trọng | E3: 0.4 | F3: 0.4 | G3: 0.3
A4: 1 | B4: TTKDGP | C4: 324 | D4: 2913 | E4: =ROUND(C4*50%,0) -> 162 | F4: =ROUND(C4*20%,0) -> 65 | G4: =ROUND(30%*E4,0) -> 49 | H4: =ROUND(D4*20%,0) -> 583 | I4: =IF(H4>200,1,IF(AND(H4<200,H4>100),2,IF(H4<100,3,0))) -> 1 | L4: TTKDGP | M4: 583 | N4: 1
A5: 2 | B5: Kỳ Sơn | C5: 8 | D5: 106 | E5: =ROUND(C5*50%,0) -> 4 | F5: =ROUND(C5*20%,0) -> 2 | G5: =ROUND(30%*E5,0) -> 1 | H5: =ROUND(D5*20%,0) -> 21 | I5: =IF(H5>200,1,IF(AND(H5<200,H5>100),2,IF(H5<100,3,0))) -> 3 | L5: Quỳnh Lưu | M5: 292 | N5: 1
A6: 3 | B6: Vinh 2 | C6: 13 | D6: 172 | E6: =ROUND(C6*50%,0) -> 7 | F6: =ROUND(C6*20%,0) -> 3 | G6: =ROUND(30%*E6,0) -> 2 | H6: =ROUND(D6*20%,0) -> 34 | I6: =IF(H6>200,1,IF(AND(H6<200,H6>100),2,IF(H6<100,3,0))) -> 3 | L6: Diễn Châu | M6: 288 | N6: 1
A7: 4 | B7: Tân Kỳ | C7: 12 | D7: 468 | E7: =ROUND(C7*50%,0) -> 6 | F7: =ROUND(C7*20%,0) -> 2 | G7: =ROUND(30%*E7,0) -> 2 | H7: =ROUND(D7*20%,0) -> 94 | I7: =IF(H7>200,1,IF(AND(H7<200,H7>100),2,IF(H7<100,3,0))) -> 3 | L7: Yên Thành | M7: 242 | N7: 1
A8: 5 | B8: Đô Lương | C8: 21 | D8: 1007 | E8: =ROUND(C8*50%,0) -> 11 | F8: =ROUND(C8*20%,0) -> 4 | G8: =ROUND(30%*E8,0) -> 3 | H8: =ROUND(D8*20%,0) -> 201 | I8: =IF(H8>200,1,IF(AND(H8<200,H8>100),2,IF(H8<100,3,0))) -> 1 | L8: Đô Lương | M8: 201 | N8: 1
A9: 6 | B9: Nghi Lộc | C9: 32 | D9: 917 | E9: =ROUND(C9*50%,0) -> 16 | F9: =ROUND(C9*20%,0) -> 6 | G9: =ROUND(30%*E9,0) -> 5 | H9: =ROUND(D9*20%,0) -> 183 | I9: =IF(H9>200,1,IF(AND(H9<200,H9>100),2,IF(H9<100,3,0))) -> 2 | L9: Nghi Lộc | M9: 183 | N9: 2
A10: 7 | B10: Quỳ Châu | C10: 5 | D10: 232 | E10: =ROUND(C10*50%,0) -> 3 | F10: =ROUND(C10*20%,0) -> 1 | G10: =ROUND(30%*E10,0) -> 1 | H10: =ROUND(D10*20%,0) -> 46 | I10: =IF(H10>200,1,IF(AND(H10<200,H10>100),2,IF(H10<100,3,0))) -> 3 | L10: Nam Đàn | M10: 167 | N10: 2
A11: 8 | B11: Anh Sơn | C11: 14 | D11: 526 | E11: =ROUND(C11*50%,0) -> 7 | F11: =ROUND(C11*20%,0) -> 3 | G11: =ROUND(30%*E11,0) -> 2 | H11: =ROUND(D11*20%,0) -> 105 | I11: =IF(H11>200,1,IF(AND(H11<200,H11>100),2,IF(H11<100,3,0))) -> 2 | L11: Nghĩa Đàn | M11: 165 | N11: 2
A12: 9 | B12: Diễn Châu | C12: 32 | D12: 1438 | E12: =ROUND(C12*50%,0) -> 16 | F12: =ROUND(C12*20%,0) -> 6 | G12: =ROUND(30%*E12,0) -> 5 | H12: =ROUND(D12*20%,0) -> 288 | I12: =IF(H12>200,1,IF(AND(H12<200,H12>100),2,IF(H12<100,3,0))) -> 1 | L12: Thanh Chương | M12: 165 | N12: 2
A13: 10 | B13: Quỳnh Lưu | C13: 51 | D13: 1458 | E13: =ROUND(C13*50%,0) -> 26 | F13: =ROUND(C13*20%,0) -> 10 | G13: =ROUND(30%*E13,0) -> 8 | H13: =ROUND(D13*20%,0) -> 292 | I13: =IF(H13>200,1,IF(AND(H13<200,H13>100),2,IF(H13<100,3,0))) -> 1 | L13: Vinh 1 | M13: 111 | N13: 2
A14: 11 | B14: Nghĩa Đàn | C14: 58 | D14: 827 | E14: =ROUND(C14*50%,0) -> 29 | F14: =ROUND(C14*20%,0) -> 12 | G14: =ROUND(30%*E14,0) -> 9 | H14: =ROUND(D14*20%,0) -> 165 | I14: =IF(H14>200,1,IF(AND(H14<200,H14>100),2,IF(H14<100,3,0))) -> 2 | L14: Anh Sơn | M14: 105 | N14: 2
A15: 12 | B15: Tương Dương | C15: 6 | D15: 115 | E15: =ROUND(C15*50%,0) -> 3 | F15: =ROUND(C15*20%,0) -> 1 | G15: =ROUND(30%*E15,0) -> 1 | H15: =ROUND(D15*20%,0) -> 23 | I15: =IF(H15>200,1,IF(AND(H15<200,H15>100),2,IF(H15<100,3,0))) -> 3 | L15: Tân Kỳ | M15: 94
A16: 13 | B16: Con Cuông | C16: 8 | D16: 226 | E16: =ROUND(C16*50%,0) -> 4 | F16: =ROUND(C16*20%,0) -> 2 | G16: =ROUND(30%*E16,0) -> 1 | H16: =ROUND(D16*20%,0) -> 45 | I16: =IF(H16>200,1,IF(AND(H16<200,H16>100),2,IF(H16<100,3,0))) -> 3 | L16: Quỳ Hợp | M16: 94
A17: 14 | B17: Yên Thành | C17: 32 | D17: 1208 | E17: =ROUND(C17*50%,0) -> 16 | F17: =ROUND(C17*20%,0) -> 6 | G17: =ROUND(30%*E17,0) -> 5 | H17: =ROUND(D17*20%,0) -> 242 | I17: =IF(H17>200,1,IF(AND(H17<200,H17>100),2,IF(H17<100,3,0))) -> 1 | L17: Quỳ Châu | M17: 46
A18: 15 | B18: Quỳ Hợp | C18: 24 | D18: 471 | E18: =ROUND(C18*50%,0) -> 12 | F18: =ROUND(C18*20%,0) -> 5 | G18: =ROUND(30%*E18,0) -> 4 | H18: =ROUND(D18*20%,0) -> 94 | I18: =IF(H18>200,1,IF(AND(H18<200,H18>100),2,IF(H18<100,3,0))) -> 3 | L18: Con Cuông | M18: 45
A19: 16 | B19: Nam Đàn | C19: 23 | D19: 837 | E19: =ROUND(C19*50%,0) -> 12 | F19: =ROUND(C19*20%,0) -> 5 | G19: =ROUND(30%*E19,0) -> 4 | H19: =ROUND(D19*20%,0) -> 167 | I19: =IF(H19>200,1,IF(AND(H19<200,H19>100),2,IF(H19<100,3,0))) -> 2 | L19: Quế Phong | M19: 36
A20: 17 | B20: Vinh 1 | C20: 13 | D20: 553 | E20: =ROUND(C20*50%,0) -> 7 | F20: =ROUND(C20*20%,0) -> 3 | G20: =ROUND(30%*E20,0) -> 2 | H20: =ROUND(D20*20%,0) -> 111 | I20: =IF(H20>200,1,IF(AND(H20<200,H20>100),2,IF(H20<100,3,0))) -> 2 | L20: Vinh 2 | M20: 34
A21: 18 | B21: Thanh Chương | C21: 27 | D21: 826 | E21: =ROUND(C21*50%,0) -> 14 | F21: =ROUND(C21*20%,0) -> 5 | G21: =ROUND(30%*E21,0) -> 4 | H21: =ROUND(D21*20%,0) -> 165 | I21: =IF(H21>200,1,IF(AND(H21<200,H21>100),2,IF(H21<100,3,0))) -> 2 | L21: Tương Dương | M21: 23
A22: 19 | B22: Quế Phong | C22: 5 | D22: 182 | E22: =ROUND(C22*50%,0) -> 3 | F22: =ROUND(C22*20%,0) -> 1 | G22: =ROUND(30%*E22,0) -> 1 | H22: =ROUND(D22*20%,0) -> 36 | I22: =IF(H22>200,1,IF(AND(H22<200,H22>100),2,IF(H22<100,3,0))) -> 3 | L22: Kỳ Sơn | M22: 21
B23: Tổng | C23: =SUM(C4:C22) -> 708 | D23: =SUM(D4:D22) -> 14482 | E23: =SUM(E4:E22) -> 358 | F23: =SUM(F4:F22) -> 142 | G23: =SUM(G4:G22) -> 109 | H23: =SUM(H4:H22) -> 2895
B27: TTKDGP | C27: 324
B28: Nghĩa Đàn | C28: 58
B29: Quỳnh Lưu | C29: 51
B30: Nghi Lộc | C30: 32
B31: Diễn Châu | C31: 32
B32: Yên Thành | C32: 32
B33: Thanh Chương | C33: 27
B34: Quỳ Hợp | C34: 24 | F34: 1 | G34: 2000000 | H34: =F34*G34 -> 2000000
B35: Nam Đàn | C35: 23 | F35: 5 | G35: 1000000 | H35: =F35*G35 -> 5000000
B36: Đô Lương | C36: 21 | F36: 13 | G36: 500000 | H36: =F36*G36 -> 6500000
B37: Anh Sơn | C37: 14 | F37: 5 | G37: 3000000 | H37: =F37*G37 -> 15000000
B38: Vinh 2 | C38: 13 | F38: 6 | G38: 2000000 | H38: =F38*G38 -> 12000000
B39: Vinh 1 | C39: 13 | F39: 8 | G39: 1000000 | H39: =F39*G39 -> 8000000
B40: Tân Kỳ | C40: 12 | H40: =SUM(H34:H39) -> 48500000
B41: Kỳ Sơn | C41: 8
B42: Con Cuông | C42: 8
B43: Tương Dương | C43: 6
...
